<?xml version="1.0"?>
<robot name="autocart">
  <link name="base_link">
    <inertial>
      <mass value="15.0"/>
      <origin xyz="0 0 0.1"/>
      <inertia ixx="1" ixy="0" ixz="0" iyy="1" iyz="0" izz="1"/>
    </inertial>
    <visual>
      <origin xyz="0 0 0.25" rpy="0 0 0"/>
      <geometry>
        <box size="0.8 0.6 0.5"/>
      </geometry>
      <material name="grey">
        <color rgba="0.7 0.7 0.7 1.0"/>
      </material>
    </visual>
    <collision>
      <origin xyz="0 0 0.25" rpy="0 0 0"/>
      <geometry>
        <box size="0.8 0.6 0.5"/>
      </geometry>
    </collision>
  </link>

  <!-- Left Wheel-->
  <link name="left_wheel">
    <inertial>
      <mass value="1.0"/>
      <origin xyz="0 0 0"/>
      <inertia ixx="0.02" ixy="0" ixz="0" iyy="0.01" iyz="0" izz="0.01"/>
    </inertial>
    <visual>
      <origin xyz="0 0 0" rpy="1.5708 0 0"/>
      <geometry>
        <cylinder radius="0.1" length="0.05"/>
      </geometry>
      <material name="black">
        <color rgba="0.1 0.1 0.1 1.0"/>
      </material>
    </visual>
    <collision>
      <origin xyz ="0 0 0" rpy="1.5708 0 0"/>
      <geometry>
        <cylinder radius="0.1" length="0.05"/>
      </geometry>
    </collision>
  </link>

  <joint name="left_wheel_joint" type="continuous">
    <parent link="base_link"/>
    <child link="left_wheel"/>
    <origin xyz="-0.2 0.35 0.1" rpy="0 0 0"/>
    <axis xyz="0 1 0"/>
  </joint>

  <!-- Right Wheel -->
  <link name="right_wheel">
    <inertial>
      <mass value="1.0"/>
      <origin xyz="0 0 0"/>
      <inertia ixx="0.01" ixy="0" ixz="0" iyy="0.01" iyz="0" izz="0.01"/>
    </inertial>
    <visual>
      <origin xyz="0 0 0" rpy="1.5708 0 0"/>
      <geometry>
        <cylinder radius="0.1" length="0.05"/>
      </geometry>
      <material name="black">
        <color rgba="0.1 0.1 0.1 1.0"/>
      </material>
    </visual>
    <collision>
      <origin xyz ="0 0 0" rpy="1.5708 0 0"/>
      <geometry>
        <cylinder radius="0.1" length="0.05"/>
      </geometry>
    </collision>
  </link>

  <joint name="right_wheel_joint" type="continuous">
    <parent link="base_link"/>
    <child link="right_wheel"/>
    <origin xyz="-0.2 -0.35 0.1" rpy="0 0 0"/>
    <axis xyz="0 1 0"/>
  </joint>

  <!-- Front Caster -->
  <link name="front_caster">
    <inertial>
      <mass value="0.5"/>
      <origin xyz="0 0 0"/>
      <inertia ixx="0.001" ixy="0" ixz="0" iyy="0.001" iyz="0" izz="0.001"/>
    </inertial>
    <visual>
      <origin xyz="0 0 0" rpy="0 0 0"/>
      <geometry>
        <sphere radius="0.05"/>
      </geometry>
      <material name="black">
        <color rgba="0.1 0.1 0.1 1.0"/>
      </material>
    </visual>
    <collision>
      <origin xyz="0 0 0" rpy="0 0 0"/>
      <geometry>
        <sphere radius="0.05"/>
      </geometry>
    </collision>
  </link>

  <joint name="front_caster_joint" type="fixed">
    <parent link="base_link"/>
    <child link="front_caster"/>
    <origin xyz="0.3 0 0.05" rpy="0 0 0"/>
  </joint>

  <!-- IMU sensor -->
  <link name="imu_link">
    <inertial>
      <mass value="0.1"/>
      <origin xyz="0 0 0.3"/>
      <inertia ixx="0.01" ixy="0" ixz="0" iyy="0.01" iyz="0" izz="0.01"/>
    </inertial>
  </link>
  <joint name="imu_joint" type="fixed">
    <parent link="base_link"/>
    <child link="imu_link"/>
    <origin xyz="0 0 0.3" rpy="0 0 0"/>
  </joint>

  <!-- Camera -->
  <link name="camera_link">
    <inertial>
      <mass value="0.1"/>
      <origin xyz="0.4 0 0.5"/>
      <inertia ixx="0.01" ixy="0" ixz="0" iyy="0.01" iyz="0" izz="0.01"/>
    </inertial>
    <visual>
      <origin xyz="0 0 0" rpy="0 0 0"/>
      <geometry>
        <box size="0.1 0.1 0.1"/>
      </geometry>
      <material name="black">
        <color rgba="0.1 0.1 0.1 1.0"/>
      </material>
    </visual>
  </link>
  <joint name="camera_joint" type="fixed">
    <parent link="base_link"/>
    <child link="camera_link"/>
    <origin xyz="0.4 0 0.5" rpy="0 0 0"/>
  </joint>

  <gazebo reference="base_link">
    <material>Gazebo/Grey</material>
  </gazebo>

  <gazebo reference="camera_link">
    <sensor type="camera" name="front_camera">
      <update_rate>15</update_rate>
      <camera>
        <horizontal_fov>1.396</horizontal_fov>
        <image>
          <width>640</width>
          <height>480</height>
          <format>R8G8B8</format>
        </image>
        <clip>
          <near>0.1</near>
          <far>50</far>
        </clip>
      </camera>
      <always_on>1</always_on>
      <visualize>true</visualize>
      <topic>camera/image</topic>
    </sensor>
  </gazebo>

  <gazebo reference="imu_link">
    <sensor name="imu_sensor" type="imu">
      <always_on>true</always_on>
      <update_rate>50</update_rate>
      <topic>imu/data</topic>
    </sensor>
  </gazebo>

  <gazebo>
  <plugin filename="libgz-sim-diff-drive-system.so" name="gz::sim::systems::DiffDrive">
    <left_joint>left_wheel_joint</left_joint>
    <right_joint>right_wheel_joint</right_joint>
    <wheel_separation>0.7</wheel_separation>
    <wheel_radius>0.1</wheel_radius>
    <max_linear_acceleration>1.0</max_linear_acceleration>
    <min_linear_acceleration>-1.0</min_linear_acceleration>
    <max_angular_acceleration>2.0</max_angular_acceleration>
    <min_angular_acceleration>-2.0</min_angular_acceleration>
    <max_linear_velocity>0.5</max_linear_velocity>
    <min_linear_velocity>-0.5</min_linear_velocity>
    <max_angular_velocity>1.0</max_angular_velocity>
    <min_angular_velocity>-1.0</min_angular_velocity>
    <topic>/cmd_vel</topic>
    <odom_topic>/odom</odom_topic>
    <frame_id>odom</frame_id>
    <child_frame_id>base_link</child_frame_id>
    <odom_publish_frequency>50</odom_publish_frequency>
  </plugin>
</gazebo>

</robot>